Workbook

Sheet FORMAS
I2: SELECCIONE FORMA | J2: SELECCIONE RUT | K2: ALUMNO
B3: FORMA | G3: RUT | I3: FORMA 01 | J3: 79473339 | K3: BUSTAMANTE BAEZ , JAVIERA ALEJANDRA
B4: SELECCIONE FORMA | G4: =VLOOKUP(B4,I:K,2,) -> SELECCIONE RUT | I4: FORMA 02 | J4: 81025168 | K4: BUSTAMANTE VENEGAS , ARACELY JEANNETTE
I5: FORMA 03 | J5: 37568226 | K5: CANDIA OLIVARES , JAVIER ANDRÉS
G6: ALUMNO | I6: FORMA 04 | J6: 79509581 | K6: CASTILLO MORENO , BÁRBARA CONSTANZA
G7: =VLOOKUP(G4,J2:K21,2,FALSE) -> ALUMNO | I7: FORMA 05 | J7: 99160009 | K7: CAÑAS CAÑAS , FRANCISCO IGNACIO
I8: FORMA 06 | J8: 48882672 | K8: DÍAZ CONTRERAS , PAULA JAVIERA
I9: FORMA 07 | J9: 60550932 | K9: GALLARDO SILVA , MAURICIO ANDRÉS*
I10: FORMA 08 | J10: 56696190 | K10: LASTRA FUENTES , YARITZA NICOLE
I11: FORMA 09 | J11: 77789015 | K11: MONTECINO ALTAMIRANO , RODOLFO ANTONIO
I12: FORMA 10 | J12: 78787183 | K12: MOREIRA SOCORRO , PAOLO
I13: FORMA 11 | J13: 26760665 | K13: MOYA JUSTO , PIERA RENATTA*
I14: FORMA 12 | J14: 79193836 | K14: MUNOZ MARTINEZ , NICOLE SOLANGE
I15: FORMA 13 | J15: 63307104 | K15: NECULQUEO AGUAYO , VERÓNICA ISABEL
I16: FORMA 14 | J16: 81236575 | K16: ORTIZ ASTORGA , NATALIA ALEJANDRA
I17: FORMA 15 | J17: 41517828 | K17: PIZARRO SÁEZ , MARÍA JOSÉ ARLETTE
I18: FORMA 16 | J18: 83397571 | K18: PLAZA BECERRA , CARLOS DANILO
I19: FORMA 17 | J19: 37927377 | K19: RAMÍREZ FLORES , KATHERINE STEPHANIE
... I21: FORMA 19 | J21: 87470251 | K21: EXTRA
I22: FORMA 20 | J22: 34496152
I23: FORMA 21 | J23: 69035824
I24: FORMA 22 | J24: 71118739
I25: FORMA 23 | J25: 35637425
I26: FORMA 24 | J26: 49338949
I27: FORMA 25 | J27: 55002986
I28: FORMA 26 | J28: 51558502
I29: FORMA 27 | J29: 80257659
I30: FORMA 28 | J30: 68618426
I31: FORMA 29 | J31: 52497317
I32: FORMA 30 | J32: 92893974

Sheet BD01
A1: Id | B1: ID | C1: GENERO | D1: GENERO | E1: ESTABLECIMIENTO | F1: ESTABLECIMIENTO | G1: PUNTAJE | H1: PUNTAJE | I1: PUNTAJE | J1: REMUNERACIÓN | K1: REMUNERACIÓN | L1: ESPECIE | M1: SECTOR | P1: PUNTAJE | Q1: REMUNERACIÓN | R1: INTEG | S1: RUT
A2: 1 | B2: 65 | C2: =VALUE(MID(U2,MOD(A2,5)+1,1)) -> #VALUE! | D2: =VLOOKUP(C2,$W$8:$X$10,2,FALSE) -> #VALUE! | E2: =VALUE(MID(U2,(5-MOD(A2,4)),1)) -> #VALUE! | F2: =VLOOKUP(E2,$W$2:$X$4,2,FALSE) -> #VALUE! | G2: =MID($W$22,MOD(ROW(G2),5)+1,1)*(-1)^ROW(G2) -> #VALUE! | H2: 284 | I2: =H2+G2 -> #VALUE! | J2: 153246 | K2: =$X$22 -> #VALUE! | L2: =VLOOKUP(O2,$Z$2:$AA$5,2,FALSE) -> #VALUE! | M2: =VLOOKUP(N2,$Z$8:$AA$10,2,FALSE) -> #VALUE! | N2: =VALUE(MID(U2,(5-MOD(A2,3)),1)) -> #VALUE! | O2: =N3+N4 -> #VALUE! | P2: 193 | Q2: 139518 | R2: 3 | S2: =FORMAS!G4 -> SELECCIONE RUT | T2: =INT(W23/2)+14 -> #VALUE! | U2: =DEC2BIN(T2) -> #VALUE! | W2: CODIGO | X2: ESTABLECIMIENTO | Z2: CODIGO | AA2: ESPECIE
A3: 2 | B3: 162 | C3: =VALUE(MID(U3,MOD(A3,5)+1,1)) -> #VALUE! | D3: =VLOOKUP(C3,$W$8:$X$10,2,FALSE) -> #VALUE! | E3: =VALUE(MID(U3,(5-MOD(A3,4)),1)) -> #VALUE! | F3: =VLOOKUP(E3,$W$2:$X$4,2,FALSE) -> #VALUE! | G3: =MID($W$22,MOD(ROW(G3),5)+1,1)*(-1)^ROW(G3) -> #VALUE! | H3: 474 | I3: =H3+G3 -> #VALUE! | J3: 128589 | K3: =$X$22 -> #VALUE! | L3: =VLOOKUP(O3,$Z$2:$AA$5,2,FALSE) -> #VALUE! | M3: =VLOOKUP(N3,$Z$8:$AA$10,2,FALSE) -> #VALUE! | N3: =VALUE(MID(U3,(5-MOD(A3,3)),1)) -> #VALUE! | O3: =N4+N5 -> #VALUE! | P3: 413 | Q3: 279949 | R3: 5 | T3: =T2+1 -> #VALUE! | U3: =DEC2BIN(T3) -> #VALUE! | V3: =MID(S2,3,1) -> L | W3: =MOD(V3,2) -> #VALUE! | X3: ALTOS DEL LIRCAY | Y3: =MID(S2,5,1) -> C | Z3: =MOD(Y3,3) -> #VALUE! | AA3: HUALO
A4: 3 | B4: 19 | C4: =VALUE(MID(U4,MOD(A4,5)+1,1)) -> #VALUE! | D4: =VLOOKUP(C4,$W$8:$X$10,2,FALSE) -> #VALUE! | E4: =VALUE(MID(U4,(5-MOD(A4,4)),1)) -> #VALUE! | F4: =VLOOKUP(E4,$W$2:$X$4,2,FALSE) -> #VALUE! | G4: =MID($W$22,MOD(ROW(G4),5)+1,1)*(-1)^ROW(G4) -> #VALUE! | H4: 146 | I4: =H4+G4 -> #VALUE! | J4: 204613 | K4: =$X$22 -> #VALUE! | L4: =VLOOKUP(O4,$Z$2:$AA$5,2,FALSE) -> #VALUE! | M4: =VLOOKUP(N4,$Z$8:$AA$10,2,FALSE) -> #VALUE! | N4: =VALUE(MID(U4,(5-MOD(A4,3)),1)) -> #VALUE! | O4: =N5+N6 -> #VALUE! | P4: 302 | Q4: 206889 | R4: 3 | T4: =T3+1 -> #VALUE! | U4: =DEC2BIN(T4) -> #VALUE! | V4: =V3+1 -> #VALUE! | W4: =MOD(V4,2) -> #VALUE! | X4: U. DE CONCEPCIÓN | Y4: =Y3+1 -> #VALUE! | Z4: =MOD(Y4,3) -> #VALUE! | AA4: ROBLE
A5: 4 | B5: 174 | C5: =VALUE(MID(U5,MOD(A5,5)+1,1)) -> #VALUE! | D5: =VLOOKUP(C5,$W$8:$X$10,2,FALSE) -> #VALUE! | E5: =VALUE(MID(U5,(5-MOD(A5,4)),1)) -> #VALUE! | F5: =VLOOKUP(E5,$W$2:$X$4,2,FALSE) -> #VALUE! | G5: =MID($W$22,MOD(ROW(G5),5)+1,1)*(-1)^ROW(G5) -> #VALUE! | H5: 748 | I5: =H5+G5 -> #VALUE! | J5: 68048 | K5: =$X$22 -> #VALUE! | L5: =VLOOKUP(O5,$Z$2:$AA$5,2,FALSE) -> #VALUE! | M5: =VLOOKUP(N5,$Z$8:$AA$10,2,FALSE) -> #VALUE! | N5: =VALUE(MID(U5,(5-MOD(A5,3)),1)) -> #VALUE! | O5: =N6+N7 -> #VALUE! | P5: 500 | Q5: 156581 | R5: 3 | T5: =T4+1 -> #VALUE! | U5: =DEC2BIN(T5) -> #VALUE! | Y5: =Y4+1 -> #VALUE! | Z5: =MOD(Y5,3) -> #VALUE! | AA5: RAULÍ
A6: 5 | B6: 220 | C6: =VALUE(MID(U6,MOD(A6,5)+1,1)) -> #VALUE! | D6: =VLOOKUP(C6,$W$8:$X$10,2,FALSE) -> #VALUE! | E6: =VALUE(MID(U6,(5-MOD(A6,4)),1)) -> #VALUE! | F6: =VLOOKUP(E6,$W$2:$X$4,2,FALSE) -> #VALUE! | G6: =MID($W$22,MOD(ROW(G6),5)+1,1)*(-1)^ROW(G6) -> #VALUE! | H6: 574 | I6: =H6+G6 -> #VALUE! | J6: 211829 | K6: =$X$22 -> #VALUE! | L6: =VLOOKUP(O6,$Z$2:$AA$5,2,FALSE) -> #VALUE! | M6: =VLOOKUP(N6,$Z$8:$AA$10,2,FALSE) -> #VALUE! | N6: =VALUE(MID(U6,(5-MOD(A6,3)),1)) -> #VALUE! | O6: =N7+N8 -> #VALUE! | P6: 306 | Q6: 135253 | R6: 3 | T6: =T5+1 -> #VALUE! | U6: =DEC2BIN(T6) -> #VALUE!
A7: 6 | B7: 8 | C7: =VALUE(MID(U7,MOD(A7,5)+1,1)) -> #VALUE! | D7: =VLOOKUP(C7,$W$8:$X$10,2,FALSE) -> #VALUE! | E7: =VALUE(MID(U7,(5-MOD(A7,4)),1)) -> #VALUE! | F7: =VLOOKUP(E7,$W$2:$X$4,2,FALSE) -> #VALUE! | G7: =MID($W$22,MOD(ROW(G7),5)+1,1)*(-1)^ROW(G7) -> #VALUE! | H7: 430 | I7: =H7+G7 -> #VALUE! | J7: 123246 | K7: =$X$22 -> #VALUE! | L7: =VLOOKUP(O7,$Z$2:$AA$5,2,FALSE) -> #VALUE! | M7: =VLOOKUP(N7,$Z$8:$AA$10,2,FALSE) -> #VALUE! | N7: =VALUE(MID(U7,(5-MOD(A7,3)),1)) -> #VALUE! | O7: =N8+N9 -> #VALUE! | P7: 331 | Q7: 97877 | R7: 4 | T7: =T6+1 -> #VALUE! | U7: =DEC2BIN(T7) -> #VALUE!
A8: 7 | B8: 74 | C8: =VALUE(MID(U8,MOD(A8,5)+1,1)) -> #VALUE! | D8: =VLOOKUP(C8,$W$8:$X$10,2,FALSE) -> #VALUE! | E8: =VALUE(MID(U8,(5-MOD(A8,4)),1)) -> #VALUE! | F8: =VLOOKUP(E8,$W$2:$X$4,2,FALSE) -> #VALUE! | G8: =MID($W$22,MOD(ROW(G8),5)+1,1)*(-1)^ROW(G8) -> #VALUE! | H8: 235 | I8: =H8+G8 -> #VALUE! | J8: 153386 | K8: =$X$22 -> #VALUE! | L8: =VLOOKUP(O8,$Z$2:$AA$5,2,FALSE) -> #VALUE! | M8: =VLOOKUP(N8,$Z$8:$AA$10,2,FALSE) -> #VALUE! | N8: =VALUE(MID(U8,(5-MOD(A8,3)),1)) -> #VALUE! | O8: =N9+N10 -> #VALUE! | P8: 288 | Q8: 207789 | R8: 4 | T8: =T7+1 -> #VALUE! | U8: =DEC2BIN(T8) -> #VALUE! | W8: CODIGO | X8: REGIÓN | Z8: CODIGO | AA8: SECTOR
A9: 8 | B9: 225 | C9: =VALUE(MID(U9,MOD(A9,5)+1,1)) -> #VALUE! | D9: =VLOOKUP(C9,$W$8:$X$10,2,FALSE) -> #VALUE! | E9: =VALUE(MID(U9,(5-MOD(A9,4)),1)) -> #VALUE! | F9: =VLOOKUP(E9,$W$2:$X$4,2,FALSE) -> #VALUE! | G9: =MID($W$22,MOD(ROW(G9),5)+1,1)*(-1)^ROW(G9) -> #VALUE! | H9: 909 | I9: =H9+G9 -> #VALUE! | J9: 135186 | K9: =$X$22 -> #VALUE! | L9: =VLOOKUP(O9,$Z$2:$AA$5,2,FALSE) -> #VALUE! | M9: =VLOOKUP(N9,$Z$8:$AA$10,2,FALSE) -> #VALUE! | N9: =VALUE(MID(U9,(5-MOD(A9,3)),1)) -> #VALUE! | O9: =N10+N11 -> #VALUE! | P9: 430 | Q9: 123246 | R9: 3 | T9: =T8+1 -> #VALUE! | U9: =DEC2BIN(T9) -> #VALUE! | V9: =MID(S2,4,1) -> E | W9: =MOD(V9,2) -> #VALUE! | X9: Región del Bío-Bío | Y9: =MID(S2,6,1) -> C | Z9: =MOD(V3,2) -> #VALUE! | AA9: PEINE
A10: 9 | B10: 57 | C10: =VALUE(MID(U10,MOD(A10,5)+1,1)) -> #VALUE! | D10: =VLOOKUP(C10,$W$8:$X$10,2,FALSE) -> #VALUE! | E10: =VALUE(MID(U10,(5-MOD(A10,4)),1)) -> #VALUE! | F10: =VLOOKUP(E10,$W$2:$X$4,2,FALSE) -> #VALUE! | G10: =MID($W$22,MOD(ROW(G10),5)+1,1)*(-1)^ROW(G10) -> #VALUE! | H10: 307 | I10: =H10+G10 -> #VALUE! | J10: 107914 | K10: =$X$22 -> #VALUE! | L10: =VLOOKUP(O10,$Z$2:$AA$5,2,FALSE) -> #VALUE! | M10: =VLOOKUP(N10,$Z$8:$AA$10,2,FALSE) -> #VALUE! | N10: =VALUE(MID(U10,(5-MOD(A10,3)),1)) -> #VALUE! | O10: =N11+N12 -> #VALUE! | P10: 119 | Q10: 162753 | R10: 3 | T10: =T9+1 -> #VALUE! | U10: =DEC2BIN(T10) -> #VALUE! | V10: =V9+1 -> #VALUE! | W10: =MOD(V10,2) -> #VALUE! | X10: Región de Ñuble | Y10: =Y9+1 -> #VALUE! | Z10: =MOD(V4,2) -> #VALUE! | AA10: CAMINO ENLADRILLADO
A11: 10 | B11: 105 | C11: =VALUE(MID(U11,MOD(A11,5)+1,1)) -> #VALUE! | D11: =VLOOKUP(C11,$W$8:$X$10,2,FALSE) -> #VALUE! | E11: =VALUE(MID(U11,(5-MOD(A11,4)),1)) -> #VALUE! | F11: =VLOOKUP(E11,$W$2:$X$4,2,FALSE) -> #VALUE! | G11: =MID($W$22,MOD(ROW(G11),5)+1,1)*(-1)^ROW(G11) -> #VALUE! | H11: 378 | I11: =H11+G11 -> #VALUE! | J11: 92827 | K11: =$X$22 -> #VALUE! | L11: =VLOOKUP(O11,$Z$2:$AA$5,2,FALSE) -> #VALUE! | M11: =VLOOKUP(N11,$Z$8:$AA$10,2,FALSE) -> #VALUE! | N11: =VALUE(MID(U11,(5-MOD(A11,3)),1)) -> #VALUE! | O11: =N12+N13 -> #VALUE! | P11: 392 | Q11: 210279 | R11: 5 | T11: =T10+1 -> #VALUE! | U11: =DEC2BIN(T11) -> #VALUE!
A12: 11 | B12: 88 | C12: =VALUE(MID(U12,MOD(A12,5)+1,1)) -> #VALUE! | D12: =VLOOKUP(C12,$W$8:$X$10,2,FALSE) -> #VALUE! | E12: =VALUE(MID(U12,(5-MOD(A12,4)),1)) -> #VALUE! | F12: =VLOOKUP(E12,$W$2:$X$4,2,FALSE) -> #VALUE! | G12: =MID($W$22,MOD(ROW(G12),5)+1,1)*(-1)^ROW(G12) -> #VALUE! | H12: 393 | I12: =H12+G12 -> #VALUE! | J12: 129369 | K12: =$X$22 -> #VALUE! | L12: =VLOOKUP(O12,$Z$2:$AA$5,2,FALSE) -> #VALUE! | M12: =VLOOKUP(N12,$Z$8:$AA$10,2,FALSE) -> #VALUE! | N12: =VALUE(MID(U12,(5-MOD(A12,3)),1)) -> #VALUE! | O12: =N13+N14 -> #VALUE! | P12: 433 | Q12: 193832 | R12: 4 | T12: =T11+1 -> #VALUE! | U12: =DEC2BIN(T12) -> #VALUE!
A13: 12 | B13: 4 | C13: =VALUE(MID(U13,MOD(A13,5)+1,1)) -> #VALUE! | D13: =VLOOKUP(C13,$W$8:$X$10,2,FALSE) -> #VALUE! | E13: =VALUE(MID(U13,(5-MOD(A13,4)),1)) -> #VALUE! | F13: =VLOOKUP(E13,$W$2:$X$4,2,FALSE) -> #VALUE! | G13: =MID($W$22,MOD(ROW(G13),5)+1,1)*(-1)^ROW(G13) -> #VALUE! | H13: 500 | I13: =H13+G13 -> #VALUE! | J13: 156581 | K13: =$X$22 -> #VALUE! | L13: =VLOOKUP(O13,$Z$2:$AA$5,2,FALSE) -> #VALUE! | M13: =VLOOKUP(N13,$Z$8:$AA$10,2,FALSE) -> #VALUE! | N13: =VALUE(MID(U13,(5-MOD(A13,3)),1)) -> #VALUE! | O13: =N14+N15 -> #VALUE! | P13: 254 | Q13: 198167 | R13: 3 | T13: =T12+1 -> #VALUE! | U13: =DEC2BIN(T13) -> #VALUE! | W13: CODIGO | X13: GÉNERO
A14: 13 | B14: 95 | C14: =VALUE(MID(U14,MOD(A14,5)+1,1)) -> #VALUE! | D14: =VLOOKUP(C14,$W$8:$X$10,2,FALSE) -> #VALUE! | E14: =VALUE(MID(U14,(5-MOD(A14,4)),1)) -> #VALUE! | F14: =VLOOKUP(E14,$W$2:$X$4,2,FALSE) -> #VALUE! | G14: =MID($W$22,MOD(ROW(G14),5)+1,1)*(-1)^ROW(G14) -> #VALUE! | H14: 229 | I14: =H14+G14 -> #VALUE! | J14: 117061 | K14: =$X$22 -> #VALUE! | L14: =VLOOKUP(O14,$Z$2:$AA$5,2,FALSE) -> #VALUE! | M14: =VLOOKUP(N14,$Z$8:$AA$10,2,FALSE) -> #VALUE! | N14: =VALUE(MID(U14,(5-MOD(A14,3)),1)) -> #VALUE! | O14: =N15+N16 -> #VALUE! | P14: 372 | Q14: 276713 | R14: 5 | T14: =T13+1 -> #VALUE! | U14: =DEC2BIN(T14) -> #VALUE! | V14: =MID(S2,5,1) -> C | W14: =MOD(V14,5) -> #VALUE! | X14: 2
A15: 14 | B15: 119 | C15: =VALUE(MID(U15,MOD(A15,5)+1,1)) -> #VALUE! | D15: =VLOOKUP(C15,$W$8:$X$10,2,FALSE) -> #VALUE! | E15: =VALUE(MID(U15,(5-MOD(A15,4)),1)) -> #VALUE! | F15: =VLOOKUP(E15,$W$2:$X$4,2,FALSE) -> #VALUE! | G15: =MID($W$22,MOD(ROW(G15),5)+1,1)*(-1)^ROW(G15) -> #VALUE! | H15: 749 | I15: =H15+G15 -> #VALUE! | J15: 320140 | K15: =$X$22 -> #VALUE! | L15: =VLOOKUP(O15,$Z$2:$AA$5,2,FALSE) -> #VALUE! | M15: =VLOOKUP(N15,$Z$8:$AA$10,2,FALSE) -> #VALUE! | N15: =VALUE(MID(U15,(5-MOD(A15,3)),1)) -> #VALUE! | O15: =N16+N17 -> #VALUE! | P15: 230 | Q15: 213906 | R15: 3 | T15: =T14+1 -> #VALUE! | U15: =DEC2BIN(T15) -> #VALUE! | V15: =V14+1 -> #VALUE! | W15: =MOD(V15,5) -> #VALUE! | X15: 3
A16: 15 | B16: 131 | C16: =VALUE(MID(U16,MOD(A16,5)+1,1)) -> #VALUE! | D16: =VLOOKUP(C16,$W$8:$X$10,2,FALSE) -> #VALUE! | E16: =VALUE(MID(U16,(5-MOD(A16,4)),1)) -> #VALUE! | F16: =VLOOKUP(E16,$W$2:$X$4,2,FALSE) -> #VALUE! | G16: =MID($W$22,MOD(ROW(G16),5)+1,1)*(-1)^ROW(G16) -> #VALUE! | H16: 192 | I16: =H16+G16 -> #VALUE! | J16: 272642 | K16: =$X$22 -> #VALUE! | L16: =VLOOKUP(O16,$Z$2:$AA$5,2,FALSE) -> #VALUE! | M16: =VLOOKUP(N16,$Z$8:$AA$10,2,FALSE) -> #VALUE! | N16: =VALUE(MID(U16,(5-MOD(A16,3)),1)) -> #VALUE! | O16: =N17+N18 -> #VALUE! | P16: 488 | Q16: 196442 | R16: 3 | T16: =T15+1 -> #VALUE! | U16: =DEC2BIN(T16) -> #VALUE! | V16: =V15+1 -> #VALUE! | W16: =MOD(V16,5) -> #VALUE! | X16: 4
A17: 16 | B17: 94 | C17: =VALUE(MID(U17,MOD(A17,5)+1,1)) -> #VALUE! | D17: =VLOOKUP(C17,$W$8:$X$10,2,FALSE) -> #VALUE! | E17: =VALUE(MID(U17,(5-MOD(A17,4)),1)) -> #VALUE! | F17: =VLOOKUP(E17,$W$2:$X$4,2,FALSE) -> #VALUE! | G17: =MID($W$22,MOD(ROW(G17),5)+1,1)*(-1)^ROW(G17) -> #VALUE! | H17: 458 | I17: =H17+G17 -> #VALUE! | J17: 96207 | K17: =$X$22 -> #VALUE! | L17: =VLOOKUP(O17,$Z$2:$AA$5,2,FALSE) -> #VALUE! | M17: =VLOOKUP(N17,$Z$8:$AA$10,2,FALSE) -> #VALUE! | N17: =VALUE(MID(U17,(5-MOD(A17,3)),1)) -> #VALUE! | O17: =N18+N19 -> #VALUE! | P17: 312 | Q17: 153103 | R17: 3 | T17: =T16+1 -> #VALUE! | U17: =DEC2BIN(T17) -> #VALUE! | V17: =V16+1 -> #VALUE! | W17: =MOD(V17,5) -> #VALUE! | X17: 5
A18: 17 | B18: 223 | C18: =VALUE(MID(U18,MOD(A18,5)+1,1)) -> #VALUE! | D18: =VLOOKUP(C18,$W$8:$X$10,2,FALSE) -> #VALUE! | E18: =VALUE(MID(U18,(5-MOD(A18,4)),1)) -> #VALUE! | F18: =VLOOKUP(E18,$W$2:$X$4,2,FALSE) -> #VALUE! | G18: =MID($W$22,MOD(ROW(G18),5)+1,1)*(-1)^ROW(G18) -> #VALUE! | H18: 733 | I18: =H18+G18 -> #VALUE! | J18: 255496 | K18: =$X$22 -> #VALUE! | L18: =VLOOKUP(O18,$Z$2:$AA$5,2,FALSE) -> #VALUE! | M18: =VLOOKUP(N18,$Z$8:$AA$10,2,FALSE) -> #VALUE! | N18: =VALUE(MID(U18,(5-MOD(A18,3)),1)) -> #VALUE! | O18: =N19+N20 -> #VALUE! | P18: 123 | Q18: 106922 | R18: 3 | T18: =T17+1 -> #VALUE! | U18: =DEC2BIN(T18) -> #VALUE! | V18: =V17+1 -> #VALUE! | W18: =MOD(V18,5) -> #VALUE! | X18: 6
A19: 18 | B19: 59 | C19: =VALUE(MID(U19,MOD(A19,5)+1,1)) -> #VALUE! | D19: =VLOOKUP(C19,$W$8:$X$10,2,FALSE) -> #VALUE! | E19: =VALUE(MID(U19,(5-MOD(A19,4)),1)) -> #VALUE! | F19: =VLOOKUP(E19,$W$2:$X$4,2,FALSE) -> #VALUE! | G19: =MID($W$22,MOD(ROW(G19),5)+1,1)*(-1)^ROW(G19) -> #VALUE! | H19: 197 | I19: =H19+G19 -> #VALUE! | J19: 261156 | K19: =$X$22 -> #VALUE! | L19: =VLOOKUP(O19,$Z$2:$AA$5,2,FALSE) -> #VALUE! | M19: =VLOOKUP(N19,$Z$8:$AA$10,2,FALSE) -> #VALUE! | N19: =VALUE(MID(U19,(5-MOD(A19,3)),1)) -> #VALUE! | O19: =N20+N21 -> #VALUE! | P19: 167 | Q19: 338623 | R19: 4 | T19: =T18+1 -> #VALUE! | U19: =DEC2BIN(T19) -> #VALUE!
A20: 19 | B20: 73 | C20: =VALUE(MID(U20,MOD(A20,5)+1,1)) -> #VALUE! | D20: =VLOOKUP(C20,$W$8:$X$10,2,FALSE) -> #VALUE! | E20: =VALUE(MID(U20,(5-MOD(A20,4)),1)) -> #VALUE! | F20: =VLOOKUP(E20,$W$2:$X$4,2,FALSE) -> #VALUE! | G20: =MID($W$22,MOD(ROW(G20),5)+1,1)*(-1)^ROW(G20) -> #VALUE! | H20: 270 | I20: =H20+G20 -> #VALUE! | J20: 136078 | K20: =$X$22 -> #VALUE! | L20: =VLOOKUP(O20,$Z$2:$AA$5,2,FALSE) -> #VALUE! | M20: =VLOOKUP(N20,$Z$8:$AA$10,2,FALSE) -> #VALUE! | N20: =VALUE(MID(U20,(5-MOD(A20,3)),1)) -> #VALUE! | O20: =N21+N22 -> #VALUE! | P20: 146 | Q20: 204613 | R20: 3 | T20: =T19+1 -> #VALUE! | U20: =DEC2BIN(T20) -> #VALUE!
A21: 20 | B21: 251 | C21: =VALUE(MID(U21,MOD(A21,5)+1,1)) -> #VALUE! | D21: =VLOOKUP(C21,$W$8:$X$10,2,FALSE) -> #VALUE! | E21: =VALUE(MID(U21,(5-MOD(A21,4)),1)) -> #VALUE! | F21: =VLOOKUP(E21,$W$2:$X$4,2,FALSE) -> #VALUE! | G21: =MID($W$22,MOD(ROW(G21),5)+1,1)*(-1)^ROW(G21) -> #VALUE! | H21: 795 | I21: =H21+G21 -> #VALUE! | J21: 243914 | K21: =$X$22 -> #VALUE! | L21: =VLOOKUP(O21,$Z$2:$AA$5,2,FALSE) -> #VALUE! | M21: =VLOOKUP(N21,$Z$8:$AA$10,2,FALSE) -> #VALUE! | N21: =VALUE(MID(U21,(5-MOD(A21,3)),1)) -> #VALUE! | O21: =N22+N23 -> #VALUE! | P21: 737 | Q21: 233725 | R21: 4 | T21: =T20+1 -> #VALUE! | U21: =DEC2BIN(T21) -> #VALUE! | W21: CODIGO | X21: GÉNERO
A22: 21 | B22: 139 | C22: =VALUE(MID(U22,MOD(A22,5)+1,1)) -> #VALUE! | D22: =VLOOKUP(C22,$W$8:$X$10,2,FALSE) -> #VALUE! | E22: =VALUE(MID(U22,(5-MOD(A22,4)),1)) -> #VALUE! | F22: =VLOOKUP(E22,$W$2:$X$4,2,FALSE) -> #VALUE! | G22: =MID($W$22,MOD(ROW(G22),5)+1,1)*(-1)^ROW(G22) -> #VALUE! | H22: 213 | I22: =H22+G22 -> #VALUE! | J22: 132497 | K22: =$X$22 -> #VALUE! | L22: =VLOOKUP(O22,$Z$2:$AA$5,2,FALSE) -> #VALUE! | M22: =VLOOKUP(N22,$Z$8:$AA$10,2,FALSE) -> #VALUE! | N22: =VALUE(MID(U22,(5-MOD(A22,3)),1)) -> #VALUE! | O22: =N23+N24 -> #VALUE! | P22: 311 | Q22: 168106 | R22: 2 | T22: =T21+1 -> #VALUE! | U22: =DEC2BIN(T22) -> #VALUE! | W22: =MID(S2,3,5) -> LECCI | X22: =W22+300000 -> #VALUE!
A23: 22 | B23: 125 | C23: =VALUE(MID(U23,MOD(A23,5)+1,1)) -> #VALUE! | D23: =VLOOKUP(C23,$W$8:$X$10,2,FALSE) -> #VALUE! | E23: =VALUE(MID(U23,(5-MOD(A23,4)),1)) -> #VALUE! | F23: =VLOOKUP(E23,$W$2:$X$4,2,FALSE) -> #VALUE! | G23: =MID($W$22,MOD(ROW(G23),5)+1,1)*(-1)^ROW(G23) -> #VALUE! | H23: 158 | I23: =H23+G23 -> #VALUE! | J23: 116959 | K23: =$X$22 -> #VALUE! | L23: =VLOOKUP(O23,$Z$2:$AA$5,2,FALSE) -> #VALUE! | M23: =VLOOKUP(N23,$Z$8:$AA$10,2,FALSE) -> #VALUE! | N23: =VALUE(MID(U23,(5-MOD(A23,3)),1)) -> #VALUE! | O23: =N24+N25 -> #VALUE! | P23: 213 | Q23: 215669 | R23: 3 | T23: =T22+1 -> #VALUE! | U23: =DEC2BIN(T23) -> #VALUE! | W23: =MID(S2,3,2) -> LE | X23: =DEC2BIN(W23) -> #VALUE!
A24: 23 | B24: 265 | C24: =VALUE(MID(U24,MOD(A24,5)+1,1)) -> #VALUE! | D24: =VLOOKUP(C24,$W$8:$X$10,2,FALSE) -> #VALUE! | E24: =VALUE(MID(U24,(5-MOD(A24,4)),1)) -> #VALUE! | F24: =VLOOKUP(E24,$W$2:$X$4,2,FALSE) -> #VALUE! | G24: =MID($W$22,MOD(ROW(G24),5)+1,1)*(-1)^ROW(G24) -> #VALUE! | H24: 650 | I24: =H24+G24 -> #VALUE! | J24: 236957 | K24: =$X$22 -> #VALUE! | L24: =VLOOKUP(O24,$Z$2:$AA$5,2,FALSE) -> #VALUE! | M24: =VLOOKUP(N24,$Z$8:$AA$10,2,FALSE) -> #VALUE! | N24: =VALUE(MID(U24,(5-MOD(A24,3)),1)) -> #VALUE! | O24: =N25+N26 -> #VALUE! | P24: 336 | Q24: 122995 | R24: 2 | T24: =T23+1 -> #VALUE! | U24: =DEC2BIN(T24) -> #VALUE!
A25: 24 | B25: 110 | C25: =VALUE(MID(U25,MOD(A25,5)+1,1)) -> #VALUE! | D25: =VLOOKUP(C25,$W$8:$X$10,2,FALSE) -> #VALUE! | E25: =VALUE(MID(U25,(5-MOD(A25,4)),1)) -> #VALUE! | F25: =VLOOKUP(E25,$W$2:$X$4,2,FALSE) -> #VALUE! | G25: =MID($W$22,MOD(ROW(G25),5)+1,1)*(-1)^ROW(G25) -> #VALUE! | H25: 489 | I25: =H25+G25 -> #VALUE! | J25: 265041 | K25: =$X$22 -> #VALUE! | L25: =VLOOKUP(O25,$Z$2:$AA$5,2,FALSE) -> #VALUE! | M25: =VLOOKUP(N25,$Z$8:$AA$10,2,FALSE) -> #VALUE! | N25: =VALUE(MID(U25,(5-MOD(A25,3)),1)) -> #VALUE! | O25: =N26+N27 -> #VALUE! | P25: 250 | Q25: 183711 | R25: 5 | T25: =T24+1 -> #VALUE! | U25: =DEC2BIN(T25) -> #VALUE!
A26: 25 | B26: 42 | C26: =VALUE(MID(U26,MOD(A26,5)+1,1)) -> #VALUE! | D26: =VLOOKUP(C26,$W$8:$X$10,2,FALSE) -> #VALUE! | E26: =VALUE(MID(U26,(5-MOD(A26,4)),1)) -> #VALUE! | F26: =VLOOKUP(E26,$W$2:$X$4,2,FALSE) -> #VALUE! | G26: =MID($W$22,MOD(ROW(G26),5)+1,1)*(-1)^ROW(G26) -> #VALUE! | H26: 107 | I26: =H26+G26 -> #VALUE! | J26: 250280 | K26: =$X$22 -> #VALUE! | L26: =VLOOKUP(O26,$Z$2:$AA$5,2,FALSE) -> #VALUE! | M26: =VLOOKUP(N26,$Z$8:$AA$10,2,FALSE) -> #VALUE! | N26: =VALUE(MID(U26,(5-MOD(A26,3)),1)) -> #VALUE! | O26: =N27+N28 -> #VALUE! | P26: 345 | Q26: 325292 | R26: 5 | T26: =T25+1 -> #VALUE! | U26: =DEC2BIN(T26) -> #VALUE!
A27: 26 | B27: 91 | C27: =VALUE(MID(U27,MOD(A27,5)+1,1)) -> #VALUE! | D27: =VLOOKUP(C27,$W$8:$X$10,2,FALSE) -> #VALUE! | E27: =VALUE(MID(U27,(5-MOD(A27,4)),1)) -> #VALUE! | F27: =VLOOKUP(E27,$W$2:$X$4,2,FALSE) -> #VALUE! | G27: =MID($W$22,MOD(ROW(G27),5)+1,1)*(-1)^ROW(G27) -> #VALUE! | H27: 341 | I27: =H27+G27 -> #VALUE! | J27: 134750 | K27: =$X$22 -> #VALUE! | L27: =VLOOKUP(O27,$Z$2:$AA$5,2,FALSE) -> #VALUE! | M27: =VLOOKUP(N27,$Z$8:$AA$10,2,FALSE) -> #VALUE! | N27: =VALUE(MID(U27,(5-MOD(A27,3)),1)) -> #VALUE! | O27: =N28+N29 -> #VALUE! | P27: 144 | Q27: 254758 | R27: 3 | T27: =T26+1 -> #VALUE! | U27: =DEC2BIN(T27) -> #VALUE!
A28: 27 | B28: 228 | C28: =VALUE(MID(U28,MOD(A28,5)+1,1)) -> #VALUE! | D28: =VLOOKUP(C28,$W$8:$X$10,2,FALSE) -> #VALUE! | E28: =VALUE(MID(U28,(5-MOD(A28,4)),1)) -> #VALUE! | F28: =VLOOKUP(E28,$W$2:$X$4,2,FALSE) -> #VALUE! | G28: =MID($W$22,MOD(ROW(G28),5)+1,1)*(-1)^ROW(G28) -> #VALUE! | H28: 525 | I28: =H28+G28 -> #VALUE! | J28: 216612 | K28: =$X$22 -> #VALUE! | L28: =VLOOKUP(O28,$Z$2:$AA$5,2,FALSE) -> #VALUE! | M28: =VLOOKUP(N28,$Z$8:$AA$10,2,FALSE) -> #VALUE! | N28: =VALUE(MID(U28,(5-MOD(A28,3)),1)) -> #VALUE! | O28: =N29+N30 -> #VALUE! | P28: 317 | Q28: 96849 | R28: 3 | T28: =T27+1 -> #VALUE! | U28: =DEC2BIN(T28) -> #VALUE!
A29: 28 | B29: 241 | C29: =VALUE(MID(U29,MOD(A29,5)+1,1)) -> #VALUE! | D29: =VLOOKUP(C29,$W$8:$X$10,2,FALSE) -> #VALUE! | E29: =VALUE(MID(U29,(5-MOD(A29,4)),1)) -> #VALUE! | F29: =VLOOKUP(E29,$W$2:$X$4,2,FALSE) -> #VALUE! | G29: =MID($W$22,MOD(ROW(G29),5)+1,1)*(-1)^ROW(G29) -> #VALUE! | H29: 859 | I29: =H29+G29 -> #VALUE! | J29: 168468 | K29: =$X$22 -> #VALUE! | L29: =VLOOKUP(O29,$Z$2:$AA$5,2,FALSE) -> #VALUE! | M29: =VLOOKUP(N29,$Z$8:$AA$10,2,FALSE) -> #VALUE! | N29: =VALUE(MID(U29,(5-MOD(A29,3)),1)) -> #VALUE! | O29: =N30+N31 -> #VALUE! | P29: 174 | Q29: 140397 | R29: 4 | T29: =T28+1 -> #VALUE! | U29: =DEC2BIN(T29) -> #VALUE!
A30: 29 | B30: 77 | C30: =VALUE(MID(U30,MOD(A30,5)+1,1)) -> #VALUE! | D30: =VLOOKUP(C30,$W$8:$X$10,2,FALSE) -> #VALUE! | E30: =VALUE(MID(U30,(5-MOD(A30,4)),1)) -> #VALUE! | F30: =VLOOKUP(E30,$W$2:$X$4,2,FALSE) -> #VALUE! | G30: =MID($W$22,MOD(ROW(G30),5)+1,1)*(-1)^ROW(G30) -> #VALUE! | H30: 269 | I30: =H30+G30 -> #VALUE! | J30: 199502 | K30: =$X$22 -> #VALUE! | L30: =VLOOKUP(O30,$Z$2:$AA$5,2,FALSE) -> #VALUE! | M30: =VLOOKUP(N30,$Z$8:$AA$10,2,FALSE) -> #VALUE! | N30: =VALUE(MID(U30,(5-MOD(A30,3)),1)) -> #VALUE! | O30: =N31+N32 -> #VALUE! | P30: 179 | Q30: 245965 | R30: 5 | T30: =T29+1 -> #VALUE! | U30: =DEC2BIN(T30) -> #VALUE!
A31: 30 | B31: 24 | C31: =VALUE(MID(U31,MOD(A31,5)+1,1)) -> #VALUE! | D31: =VLOOKUP(C31,$W$8:$X$10,2,FALSE) -> #VALUE! | E31: =VALUE(MID(U31,(5-MOD(A31,4)),1)) -> #VALUE! | F31: =VLOOKUP(E31,$W$2:$X$4,2,FALSE) -> #VALUE! | G31: =MID($W$22,MOD(ROW(G31),5)+1,1)*(-1)^ROW(G31) -> #VALUE! | H31: 250 | I31: =H31+G31 -> #VALUE! | J31: 183711 | K31: =$X$22 -> #VALUE! | L31: =VLOOKUP(O31,$Z$2:$AA$5,2,FALSE) -> #VALUE! | M31: =VLOOKUP(N31,$Z$8:$AA$10,2,FALSE) -> #VALUE! | N31: =VALUE(MID(U31,(5-MOD(A31,3)),1)) -> #VALUE! | O31: =N32+N33 -> #VALUE! | P31: 298 | Q31: 135485 | R31: 3 | T31: =T30+1 -> #VALUE! | U31: =DEC2BIN(T31) -> #VALUE!
A32: 31 | B32: 126 | C32: =VALUE(MID(U32,MOD(A32,5)+1,1)) -> #VALUE! | D32: =VLOOKUP(C32,$W$8:$X$10,2,FALSE) -> #VALUE! | E32: =VALUE(MID(U32,(5-MOD(A32,4)),1)) -> #VALUE! | F32: =VLOOKUP(E32,$W$2:$X$4,2,FALSE) -> #VALUE! | G32: =MID($W$22,MOD(ROW(G32),5)+1,1)*(-1)^ROW(G32) -> #VALUE! | H32: 245 | I32: =H32+G32 -> #VALUE! | J32: 104995 | K32: =$X$22 -> #VALUE! | L32: =VLOOKUP(O32,$Z$2:$AA$5,2,FALSE) -> #VALUE! | M32: =VLOOKUP(N32,$Z$8:$AA$10,2,FALSE) -> #VALUE! | N32: =VALUE(MID(U32,(5-MOD(A32,3)),1)) -> #VALUE! | O32: =N33+N34 -> #VALUE! | P32: 177 | Q32: 203153 | R32: 4 | T32: =T31+1 -> #VALUE! | U32: =DEC2BIN(T32) -> #VALUE!
A33: 32 | B33: 29 | C33: =VALUE(MID(U33,MOD(A33,5)+1,1)) -> #VALUE! | D33: =VLOOKUP(C33,$W$8:$X$10,2,FALSE) -> #VALUE! | E33: =VALUE(MID(U33,(5-MOD(A33,4)),1)) -> #VALUE! | F33: =VLOOKUP(E33,$W$2:$X$4,2,FALSE) -> #VALUE! | G33: =MID($W$22,MOD(ROW(G33),5)+1,1)*(-1)^ROW(G33) -> #VALUE! | H33: 179 | I33: =H33+G33 -> #VALUE! | J33: 245965 | K33: =$X$22 -> #VALUE! | L33: =VLOOKUP(O33,$Z$2:$AA$5,2,FALSE) -> #VALUE! | M33: =VLOOKUP(N33,$Z$8:$AA$10,2,FALSE) -> #VALUE! | N33: =VALUE(MID(U33,(5-MOD(A33,3)),1)) -> #VALUE! | O33: =N34+N35 -> #VALUE! | P33: 433 | Q33: 160876 | R33: 3 | T33: =T32+1 -> #VALUE! | U33: =DEC2BIN(T33) -> #VALUE!
A34: 33 | B34: 183 | C34: =VALUE(MID(U34,MOD(A34,5)+1,1)) -> #VALUE! | D34: =VLOOKUP(C34,$W$8:$X$10,2,FALSE) -> #VALUE! | E34: =VALUE(MID(U34,(5-MOD(A34,4)),1)) -> #VALUE! | F34: =VLOOKUP(E34,$W$2:$X$4,2,FALSE) -> #VALUE! | G34: =MID($W$22,MOD(ROW(G34),5)+1,1)*(-1)^ROW(G34) -> #VALUE! | H34: 791 | I34: =H34+G34 -> #VALUE! | J34: 341000 | K34: =$X$22 -> #VALUE! | L34: =VLOOKUP(O34,$Z$2:$AA$5,2,FALSE) -> #VALUE! | M34: =VLOOKUP(N34,$Z$8:$AA$10,2,FALSE) -> #VALUE! | N34: =VALUE(MID(U34,(5-MOD(A34,3)),1)) -> #VALUE! | O34: =N35+N36 -> #VALUE! | P34: 393 | Q34: 220604 | R34: 2 | T34: =T33+1 -> #VALUE! | U34: =DEC2BIN(T34) -> #VALUE!
A35: 34 | B35: 117 | C35: =VALUE(MID(U35,MOD(A35,5)+1,1)) -> #VALUE! | D35: =VLOOKUP(C35,$W$8:$X$10,2,FALSE) -> #VALUE! | E35: =VALUE(MID(U35,(5-MOD(A35,4)),1)) -> #VALUE! | F35: =VLOOKUP(E35,$W$2:$X$4,2,FALSE) -> #VALUE! | G35: =MID($W$22,MOD(ROW(G35),5)+1,1)*(-1)^ROW(G35) -> #VALUE! | H35: 244 | I35: =H35+G35 -> #VALUE! | J35: 227585 | K35: =$X$22 -> #VALUE! | L35: =VLOOKUP(O35,$Z$2:$AA$5,2,FALSE) -> #VALUE! | M35: =VLOOKUP(N35,$Z$8:$AA$10,2,FALSE) -> #VALUE! | N35: =VALUE(MID(U35,(5-MOD(A35,3)),1)) -> #VALUE! | O35: =N36+N37 -> #VALUE! | P35: 180 | Q35: 219201 | R35: 4 | T35: =T34+1 -> #VALUE! | U35: =DEC2BIN(T35) -> #VALUE!
... A281: 280 | B281: 267 | C281: =VALUE(MID(U281,MOD(A281,5)+1,1)) -> #VALUE! | D281: =VLOOKUP(C281,$W$8:$X$10,2,FALSE) -> #VALUE! | E281: =VALUE(MID(U281,(5-MOD(A281,4)),1)) -> #VALUE! | F281: =VLOOKUP(E281,$W$2:$X$4,2,FALSE) -> #VALUE! | G281: =MID($W$22,MOD(ROW(G281),5)+1,1)*(-1)^ROW(G281) -> #VALUE! | H281: 674 | I281: =H281+G281 -> #VALUE! | J281: 260903 | K281: =$X$22 -> #VALUE! | L281: =VLOOKUP(O281,$Z$2:$AA$5,2,FALSE) -> #VALUE! | M281: =VLOOKUP(N281,$Z$8:$AA$10,2,FALSE) -> #VALUE! | N281: =VALUE(MID(U281,(5-MOD(A281,3)),1)) -> #VALUE! | O281: =N282+N283 -> #VALUE! | P281: 789 | Q281: 166343 | R281: 5 | T281: =T280+1 -> #VALUE! | U281: =DEC2BIN(T281) -> #VALUE!
J282: 313757 | K282: =$X$22 -> #VALUE! | L282: =VLOOKUP(O282,$Z$2:$AA$5,2,FALSE) -> #VALUE! | M282: =VLOOKUP(N282,$Z$8:$AA$10,2,FALSE) -> #VALUE! | N282: =VALUE(MID(U282,(5-MOD(A282,3)),1)) -> #VALUE! | O282: =N283+N284 -> #VALUE! | Q282: 313757 | T282: =T281+1 -> #VALUE! | U282: =DEC2BIN(T282) -> #VALUE!
J283: 147940 | K283: =$X$22 -> #VALUE! | L283: =VLOOKUP(O283,$Z$2:$AA$5,2,FALSE) -> #VALUE! | M283: =VLOOKUP(N283,$Z$8:$AA$10,2,FALSE) -> #VALUE! | N283: =VALUE(MID(U283,(5-MOD(A283,3)),1)) -> #VALUE! | O283: =N284+N285 -> #VALUE! | Q283: 147940 | T283: =T282+1 -> #VALUE! | U283: =DEC2BIN(T283) -> #VALUE!
J284: 113716 | K284: =$X$22 -> #VALUE! | L284: =VLOOKUP(O284,$Z$2:$AA$5,2,FALSE) -> #VALUE! | M284: =VLOOKUP(N284,$Z$8:$AA$10,2,FALSE) -> #VALUE! | N284: =VALUE(MID(U284,(5-MOD(A284,3)),1)) -> #VALUE! | O284: =N285+N286 -> #VALUE! | Q284: 113716 | T284: =T283+1 -> #VALUE! | U284: =DEC2BIN(T284) -> #VALUE!
J285: 321310 | K285: =$X$22 -> #VALUE! | L285: =VLOOKUP(O285,$Z$2:$AA$5,2,FALSE) -> #VALUE! | M285: =VLOOKUP(N285,$Z$8:$AA$10,2,FALSE) -> #VALUE! | N285: =VALUE(MID(U285,(5-MOD(A285,3)),1)) -> #VALUE! | O285: =N286+N287 -> #VALUE! | Q285: 321310 | T285: =T284+1 -> #VALUE! | U285: =DEC2BIN(T285) -> #VALUE!
...

Sheet Registro
A1: ID | B1: ESPECIE NATIVA | C1: SECTOR
A2: 1 | B2: ='BD01'!L2 -> #VALUE! | C2: ='BD01'!M2 -> #VALUE!
A3: 2 | B3: ='BD01'!L3 -> #VALUE! | C3: ='BD01'!M3 -> #VALUE!
A4: 3 | B4: ='BD01'!L4 -> #VALUE! | C4: ='BD01'!M4 -> #VALUE!
A5: 4 | B5: ='BD01'!L5 -> #VALUE! | C5: ='BD01'!M5 -> #VALUE!
A6: 5 | B6: ='BD01'!L6 -> #VALUE! | C6: ='BD01'!M6 -> #VALUE!
A7: 6 | B7: ='BD01'!L7 -> #VALUE! | C7: ='BD01'!M7 -> #VALUE!
A8: 7 | B8: ='BD01'!L8 -> #VALUE! | C8: ='BD01'!M8 -> #VALUE!
A9: 8 | B9: ='BD01'!L9 -> #VALUE! | C9: ='BD01'!M9 -> #VALUE!
A10: 9 | B10: ='BD01'!L10 -> #VALUE! | C10: ='BD01'!M10 -> #VALUE!
A11: 10 | B11: ='BD01'!L11 -> #VALUE! | C11: ='BD01'!M11 -> #VALUE!
A12: 11 | B12: ='BD01'!L12 -> #VALUE! | C12: ='BD01'!M12 -> #VALUE!
A13: 12 | B13: ='BD01'!L13 -> #VALUE! | C13: ='BD01'!M13 -> #VALUE!
... A401: 400 | B401: ='BD01'!L401 -> #VALUE! | C401: ='BD01'!M401 -> #VALUE!

Sheet Registro.EDIT
A1: ID | B1: ESPECIE NATIVA | C1: SECTOR
A2: 1 | B2: ='BD01'!L2 -> #VALUE! | C2: ='BD01'!M2 -> #VALUE!
A3: 2 | B3: ='BD01'!L3 -> #VALUE! | C3: ='BD01'!M3 -> #VALUE! | G3: Para desbloquear esta hoja vaya a la pestaña REVISAR y elija la opción DESPROTEGER HOJA
A4: 3 | B4: ='BD01'!L4 -> #VALUE! | C4: ='BD01'!M4 -> #VALUE!
A5: 4 | B5: ='BD01'!L5 -> #VALUE! | C5: ='BD01'!M5 -> #VALUE!
A6: 5 | B6: ='BD01'!L6 -> #VALUE! | C6: ='BD01'!M6 -> #VALUE!
A7: 6 | B7: ='BD01'!L7 -> #VALUE! | C7: ='BD01'!M7 -> #VALUE!
A8: 7 | B8: ='BD01'!L8 -> #VALUE! | C8: ='BD01'!M8 -> #VALUE!
A9: 8 | B9: ='BD01'!L9 -> #VALUE! | C9: ='BD01'!M9 -> #VALUE!
A10: 9 | B10: ='BD01'!L10 -> #VALUE! | C10: ='BD01'!M10 -> #VALUE!
A11: 10 | B11: ='BD01'!L11 -> #VALUE! | C11: ='BD01'!M11 -> #VALUE!
A12: 11 | B12: ='BD01'!L12 -> #VALUE! | C12: ='BD01'!M12 -> #VALUE!
A13: 12 | B13: ='BD01'!L13 -> #VALUE! | C13: ='BD01'!M13 -> #VALUE!
A14: 13 | B14: ='BD01'!L14 -> #VALUE! | C14: ='BD01'!M14 -> #VALUE!
A15: 14 | B15: ='BD01'!L15 -> #VALUE! | C15: ='BD01'!M15 -> #VALUE!
... A401: 400 | B401: ='BD01'!L401 -> #VALUE! | C401: ='BD01'!M401 -> #VALUE!

Sheet romana 2
C1: A | D1: B | J1: 466 | K1: 1 | L1: 466
A2: 281 | B2: 1 | C2: 1 | D2: 251 | E2: 662487 | F2: 4 | J2: 251 | K2: 1 | L2: 251 | AJ2: 1 | AL2: =IF(AJ2=1,"MASCULINO","FEMENINO") -> MASCULINO | AM2: 251
A3: 282 | B3: 1 | C3: 1 | D3: 236 | E3: 349927 | F3: 3 | H3: 0 | I3: 401 | J3: 236 | K3: 1 | L3: 236 | U3: Indicador | V3: Puntaje | AJ3: 1 | AL3: =IF(AJ3=1,"MASCULINO","FEMENINO") -> MASCULINO | AM3: 236
A4: 283 | B4: 1 | C4: 1 | D4: 767 | E4: 462593 | F4: 4 | H4: 0 | I4: 792 | J4: 767 | K4: 1 | L4: 767 | U4: Promedio | V4: =AVERAGE(D:D) -> 481.11429 | Y4: Género | Z4: Cantidad de estudiantes | AA4: Porcentaje | AJ4: 1 | AL4: =IF(AJ4=1,"MASCULINO","FEMENINO") -> MASCULINO | AM4: 767
A5: 284 | B5: 1 | C5: 1 | D5: 466 | E5: 374157 | F5: 5 | H5: 0 | I5: 271 | J5: 474 | K5: 1 | L5: 474 | U5: Mediana | V5: =MEDIAN(D:D) -> 463.5 | X5: 1 | Y5: MASCULINO | Z5: =COUNTIF(B:B,1) -> 76 | AA5: =Z5/Z7 -> 0.54285714 | AJ5: 1 | AL5: =IF(AJ5=1,"MASCULINO","FEMENINO") -> MASCULINO | AM5: 466
A6: 285 | B6: 1 | C6: 1 | D6: 474 | E6: 497144 | F6: 4 | H6: 0 | I6: 957 | J6: 785 | K6: 1 | L6: 785 | U6: Moda | V6: =MODE(D:D) -> 767 | X6: 0 | Y6: FEMENINO | Z6: =Z7-Z5 -> 64 | AA6: =Z6/Z7 -> 0.45714286 | AJ6: 1 | AL6: =IF(AJ6=1,"MASCULINO","FEMENINO") -> MASCULINO | AM6: 474
A7: 286 | B7: 1 | C7: 1 | D7: 785 | E7: 457891 | F7: 4 | H7: 0 | I7: 66 | J7: 11 | K7: 1 | L7: 11 | Y7: Total | Z7: =COUNT(F:F) -> 140 | AA7: 1 | AJ7: 1 | AL7: =IF(AJ7=1,"MASCULINO","FEMENINO") -> MASCULINO | AM7: 785
A8: 287 | B8: 0 | C8: 0 | D8: 401 | E8: 523302 | F8: 3 | H8: 0 | I8: 928 | J8: 643 | K8: 1 | L8: 643 | Q8: Indicador | R8: General | U8: Indicador | V8: Puntaje | AJ8: 0 | AL8: =IF(AJ8=1,"MASCULINO","FEMENINO") -> FEMENINO | AM8: 401
A9: 288 | B9: 0 | C9: 0 | D9: 792 | E9: 635397 | F9: 3 | H9: 0 | I9: 578 | J9: 466 | K9: 1 | L9: 466 | Q9: Mínimo | R9: =MIN(D:D) -> 11 | U9: Desviación estándar | V9: =STDEV(D:D) -> 208.35644 | AJ9: 0 | AL9: =IF(AJ9=1,"MASCULINO","FEMENINO") -> FEMENINO | AM9: 792
A10: 289 | B10: 1 | C10: 1 | D10: 11 | E10: 535674 | F10: 4 | H10: 0 | I10: 391 | J10: 333 | K10: 1 | L10: 333 | Q10: Q1 (25%) | R10: =QUARTILE(D:D,1) -> 332.25 | U10: Rango | V10: =R13-R9 -> 982 | AJ10: 1 | AL10: =IF(AJ10=1,"MASCULINO","FEMENINO") -> MASCULINO | AM10: 11
A11: 290 | B11: 0 | C11: 0 | D11: 271 | E11: 1047089 | F11: 3 | H11: 0 | I11: 525 | J11: 515 | K11: 1 | L11: 515 | Q11: Q2 (50%) | R11: =QUARTILE(D:D,2) -> 463.5 | U11: Rango Intercuartil | V11: =R12-R10 -> 301.75 | AJ11: 0 | AL11: =IF(AJ11=1,"MASCULINO","FEMENINO") -> FEMENINO | AM11: 271
A12: 291 | B12: 0 | C12: 0 | D12: 957 | E12: 801736 | F12: 4 | H12: 0 | I12: 116 | J12: 647 | K12: 1 | L12: 647 | Q12: Q3 (75%) | R12: =QUARTILE(D:D,3) -> 634 | U12: Coeficiente de variación | V12: =V9/V4 -> 0.43307056 | AJ12: 0 | AL12: =IF(AJ12=1,"MASCULINO","FEMENINO") -> FEMENINO | AM12: 957
A13: 292 | B13: 1 | C13: 1 | D13: 643 | E13: 523595 | F13: 3 | H13: 0 | I13: 723 | J13: 274 | K13: 1 | L13: 274 | Q13: Máximo | R13: =MAX(D:D) -> 993 | AJ13: 1 | AL13: =IF(AJ13=1,"MASCULINO","FEMENINO") -> MASCULINO | AM13: 643
A14: 293 | B14: 0 | C14: 0 | D14: 66 | E14: 503085 | F14: 3 | H14: 0 | I14: 338 | J14: 825 | K14: 1 | L14: 825 | N14: Promedio Puntaje (Masculino) | O14: =AVERAGEIFS(D:D,B:B,1) -> 466.76316 | AJ14: 0 | AL14: =IF(AJ14=1,"MASCULINO","FEMENINO") -> FEMENINO | AM14: 66
A15: 294 | B15: 1 | C15: 1 | D15: 466 | E15: 562798 | F15: 3 | H15: 0 | I15: 496 | J15: 523 | K15: 1 | L15: 523 | N15: Promedio Puntaje (Femenino) | O15: =AVERAGEIFS(D:D,B:B,0) -> 498.15625 | AJ15: 1 | AL15: =IF(AJ15=1,"MASCULINO","FEMENINO") -> MASCULINO | AM15: 466
A16: 295 | B16: 1 | C16: 1 | D16: 333 | E16: 354930 | F16: 4 | H16: 0 | I16: 426 | J16: 495 | K16: 1 | L16: 495 | Q16: Indicador | R16: FEMENINO | S16: MASCULINO | AJ16: 1 | AL16: =IF(AJ16=1,"MASCULINO","FEMENINO") -> MASCULINO | AM16: 333
A17: 296 | B17: 0 | C17: 0 | D17: 928 | E17: 371390 | F17: 3 | H17: 0 | I17: 558 | J17: 530 | K17: 1 | L17: 530 | Q17: Mínimo | R17: =MIN(I:I) -> 66 | S17: =MIN(J:J) -> 11 | AJ17: 0 | AL17: =IF(AJ17=1,"MASCULINO","FEMENINO") -> FEMENINO | AM17: 928
A18: 297 | B18: 0 | C18: 0 | D18: 578 | E18: 485926 | F18: 3 | H18: 0 | I18: 833 | J18: 711 | K18: 1 | L18: 711 | Q18: Q1 (25%) | R18: =QUARTILE(I:I,1) -> 347.75 | S18: =QUARTILE(J:J,1) -> 289.25 | AJ18: 0 | AL18: =IF(AJ18=1,"MASCULINO","FEMENINO") -> FEMENINO | AM18: 578
A19: 298 | B19: 1 | C19: 1 | D19: 515 | E19: 303537 | F19: 4 | H19: 0 | I19: 398 | J19: 285 | K19: 1 | L19: 285 | Q19: Q2 (50%) | R19: =QUARTILE(I:I,2) -> 466 | S19: =QUARTILE(J:J,2) -> 460 | AJ19: 1 | AL19: =IF(AJ19=1,"MASCULINO","FEMENINO") -> MASCULINO | AM19: 515
A20: 299 | B20: 0 | C20: 0 | D20: 391 | E20: 634971 | F20: 4 | H20: 0 | I20: 395 | J20: 993 | K20: 1 | L20: 993 | Q20: Q3 (75%) | R20: =QUARTILE(I:I,3) -> 639 | S20: =QUARTILE(J:J,3) -> 627.75 | AJ20: 0 | AL20: =IF(AJ20=1,"MASCULINO","FEMENINO") -> FEMENINO | AM20: 391
A21: 300 | B21: 1 | C21: 1 | D21: 647 | E21: 465813 | F21: 3 | H21: 0 | I21: 650 | J21: 171 | K21: 1 | L21: 171 | Q21: Máximo | R21: =MAX(I:I) -> 983 | S21: =MAX(J:J) -> 993 | AJ21: 1 | AL21: =IF(AJ21=1,"MASCULINO","FEMENINO") -> MASCULINO | AM21: 647
A22: 301 | B22: 0 | C22: 0 | D22: 525 | E22: 329930 | F22: 4 | H22: 0 | I22: 923 | J22: 464 | K22: 1 | L22: 464 | AJ22: 0 | AL22: =IF(AJ22=1,"MASCULINO","FEMENINO") -> FEMENINO | AM22: 525
A23: 302 | B23: 0 | C23: 0 | D23: 116 | E23: 436033 | F23: 3 | H23: 0 | I23: 463 | J23: 414 | K23: 1 | L23: 414 | AJ23: 0 | AL23: =IF(AJ23=1,"MASCULINO","FEMENINO") -> FEMENINO | AM23: 116
A24: 303 | B24: 0 | C24: 0 | D24: 723 | E24: 537431 | F24: 3 | H24: 0 | I24: 259 | J24: 370 | K24: 1 | L24: 370 | AJ24: 0 | AL24: =IF(AJ24=1,"MASCULINO","FEMENINO") -> FEMENINO | AM24: 723
A25: 304 | B25: 1 | C25: 1 | D25: 274 | E25: 495696 | F25: 3 | H25: 0 | I25: 425 | J25: 200 | K25: 1 | L25: 200 | AJ25: 1 | AL25: =IF(AJ25=1,"MASCULINO","FEMENINO") -> MASCULINO | AM25: 274
A26: 305 | B26: 0 | C26: 0 | D26: 338 | E26: 591597 | F26: 3 | H26: 0 | I26: 526 | J26: 513 | K26: 1 | L26: 513 | AJ26: 0 | AL26: =IF(AJ26=1,"MASCULINO","FEMENINO") -> FEMENINO | AM26: 338
A27: 306 | B27: 1 | C27: 1 | D27: 825 | E27: 417169 | F27: 4 | H27: 0 | I27: 337 | J27: 290 | K27: 1 | L27: 290 | AJ27: 1 | AL27: =IF(AJ27=1,"MASCULINO","FEMENINO") -> MASCULINO | AM27: 825
A28: 307 | B28: 1 | C28: 1 | D28: 523 | E28: 514312 | F28: 4 | H28: 0 | I28: 469 | J28: 613 | K28: 1 | L28: 613 | AJ28: 1 | AL28: =IF(AJ28=1,"MASCULINO","FEMENINO") -> MASCULINO | AM28: 523
A29: 308 | B29: 0 | C29: 0 | D29: 496 | E29: 339501 | F29: 3 | H29: 0 | I29: 330 | J29: 485 | K29: 1 | L29: 485 | V29: 0 | W29: 100 | X29: =CONCATENATE("( ",V29," - ",W29," ]") -> ( 0 - 100 ] | Y29: =COUNTIFS(D:D,">"&V29,D:D,"<="&W29) -> 3 | AJ29: 0 | AL29: =IF(AJ29=1,"MASCULINO","FEMENINO") -> FEMENINO | AM29: 496
A30: 309 | B30: 1 | C30: 1 | D30: 495 | E30: 446927 | F30: 3 | H30: 0 | I30: 645 | J30: 402 | K30: 1 | L30: 402 | V30: 100 | W30: 200 | X30: =CONCATENATE("( ",V30," - ",W30," ]") -> ( 100 - 200 ] | Y30: =COUNTIFS(D:D,">"&V30,D:D,"<="&W30) -> 7 | AJ30: 1 | AL30: =IF(AJ30=1,"MASCULINO","FEMENINO") -> MASCULINO | AM30: 495
A31: 310 | B31: 1 | C31: 1 | D31: 530 | E31: 422781 | F31: 5 | H31: 0 | I31: 658 | J31: 566 | K31: 1 | L31: 566 | V31: 200 | W31: 300 | X31: =CONCATENATE("( ",V31," - ",W31," ]") -> ( 200 - 300 ] | Y31: =COUNTIFS(D:D,">"&V31,D:D,"<="&W31) -> 22 | AJ31: 1 | AL31: =IF(AJ31=1,"MASCULINO","FEMENINO") -> MASCULINO | AM31: 530
A32: 311 | B32: 0 | C32: 0 | D32: 426 | E32: 357866 | F32: 3 | H32: 0 | I32: 692 | J32: 304 | K32: 1 | L32: 304 | V32: 300 | W32: 400 | X32: =CONCATENATE("( ",V32," - ",W32," ]") -> ( 300 - 400 ] | Y32: =COUNTIFS(D:D,">"&V32,D:D,"<="&W32) -> 21 | AJ32: 0 | AL32: =IF(AJ32=1,"MASCULINO","FEMENINO") -> FEMENINO | AM32: 426
A33: 312 | B33: 0 | C33: 0 | D33: 558 | E33: 663870 | F33: 6 | H33: 0 | I33: 551 | J33: 758 | K33: 1 | L33: 758 | V33: 400 | W33: 500 | X33: =CONCATENATE("( ",V33," - ",W33," ]") -> ( 400 - 500 ] | Y33: =COUNTIFS(D:D,">"&V33,D:D,"<="&W33) -> 28 | AJ33: 0 | AL33: =IF(AJ33=1,"MASCULINO","FEMENINO") -> FEMENINO | AM33: 558
A34: 313 | B34: 0 | C34: 0 | D34: 833 | E34: 500623 | F34: 2 | H34: 0 | I34: 240 | J34: 409 | K34: 1 | L34: 409 | V34: 500 | W34: 600 | X34: =CONCATENATE("( ",V34," - ",W34," ]") -> ( 500 - 600 ] | Y34: =COUNTIFS(D:D,">"&V34,D:D,"<="&W34) -> 18 | AJ34: 0 | AL34: =IF(AJ34=1,"MASCULINO","FEMENINO") -> FEMENINO | AM34: 833
A35: 314 | B35: 1 | C35: 1 | D35: 711 | E35: 423136 | F35: 3 | H35: 0 | I35: 379 | J35: 633 | K35: 1 | L35: 633 | V35: 600 | W35: 700 | X35: =CONCATENATE("( ",V35," - ",W35," ]") -> ( 600 - 700 ] | Y35: =COUNTIFS(D:D,">"&V35,D:D,"<="&W35) -> 16 | AJ35: 1 | AL35: =IF(AJ35=1,"MASCULINO","FEMENINO") -> MASCULINO | AM35: 711
A36: 315 | B36: 1 | C36: 1 | D36: 285 | E36: 498499 | F36: 4 | H36: 0 | I36: 402 | J36: 543 | K36: 1 | L36: 543 | V36: 700 | W36: 800 | X36: =CONCATENATE("( ",V36," - ",W36," ]") -> ( 700 - 800 ] | Y36: =COUNTIFS(D:D,">"&V36,D:D,"<="&W36) -> 16 | AJ36: 1 | AL36: =IF(AJ36=1,"MASCULINO","FEMENINO") -> MASCULINO | AM36: 285
A37: 316 | B37: 1 | C37: 1 | D37: 993 | E37: 513852 | F37: 4 | H37: 0 | I37: 385 | J37: 409 | K37: 1 | L37: 409 | V37: 800 | W37: 900 | X37: =CONCATENATE("( ",V37," - ",W37," ]") -> ( 800 - 900 ] | Y37: =COUNTIFS(D:D,">"&V37,D:D,"<="&W37) -> 4 | AJ37: 1 | AL37: =IF(AJ37=1,"MASCULINO","FEMENINO") -> MASCULINO | AM37: 993
A38: 317 | B38: 1 | C38: 1 | D38: 171 | E38: 393008 | F38: 4 | H38: 0 | I38: 607 | J38: 713 | K38: 1 | L38: 713 | V38: 900 | W38: 1000 | X38: =CONCATENATE("( ",V38," - ",W38," ]") -> ( 900 - 1000 ] | Y38: =COUNTIFS(D:D,">"&V38,D:D,"<="&W38) -> 5 | AJ38: 1 | AL38: =IF(AJ38=1,"MASCULINO","FEMENINO") -> MASCULINO | AM38: 171
A39: 318 | B39: 1 | C39: 1 | D39: 464 | E39: 314214 | F39: 3 | H39: 0 | I39: 795 | J39: 738 | K39: 1 | L39: 738 | X39: Total | Y39: =SUM(Y29:Y38) -> 140 | AJ39: 1 | AL39: =IF(AJ39=1,"MASCULINO","FEMENINO") -> MASCULINO | AM39: 464
A40: 319 | B40: 0 | C40: 0 | D40: 398 | E40: 671576 | F40: 3 | H40: 0 | I40: 625 | J40: 559 | K40: 1 | L40: 559 | AJ40: 0 | AL40: =IF(AJ40=1,"MASCULINO","FEMENINO") -> FEMENINO | AM40: 398
...
